<?xml version="1.0" ?>
<robot name="ackermann_vehicle">

  <!-- Podstawowa struktura pojazdu -->
  <link name="base_link">
    <visual>
      <geometry>
        <box size="0.2 0.1 0.06"/>
      </geometry>
      <material name="red">
        <color rgba="0.8 0.0 0.0 1.0"/>
      </material>
    </visual>
    <collision>
      <geometry>
        <box size="0.2 0.1 0.15"/>
      </geometry>
    </collision>
    <inertial>
      <mass value="10.0"/>
      <inertia ixx="0.1" ixy="0.0" ixz="0.0" iyy="0.1" iyz="0.0" izz="0.1"/>
    </inertial>
  </link>

  <link name="base_footprint"/>

  <joint name="base_joint" type="fixed">
        <parent link="base_link"/>
        <child link="base_footprint"/>
        <origin xyz="-0.1 0.0 -0.05" rpy="0 0 0"/>
    </joint>

  <!-- Przednie lewe koło -->
  <link name="wheel_front_left">
    <visual>
      <geometry>
        <cylinder length="0.02" radius="0.08"/>
      </geometry>
      <material name="black">
        <color rgba="0.0 0.0 0.0 1.0"/>
      </material>
    </visual>
    <collision>
      <geometry>
        <sphere radius="0.08"/>
      </geometry>
    </collision>
    <inertial>
      <mass value="1.0"/>
      <inertia ixx="0.05" ixy="0.0" ixz="0.0" iyy="0.05" iyz="0.0" izz="0.05"/>
    </inertial>
  </link>

  <!-- Joint łączący bazę z przednim lewym punktem skrętu -->
  <joint name="left_steering_joint" type="continuous">
    <parent link="base_link"/>
    <child link="steering_left"/>
    <origin xyz="0.1 0.06 -0.03" rpy="0 0 0"/>
    <axis xyz="0 0 1"/>
  </joint>

  <!-- Przedni lewy punkt skrętu -->
  <link name="steering_left">
    <inertial>
      <mass value="0.1"/>
      <inertia ixx="0.001" ixy="0.0" ixz="0.0" iyy="0.001" iyz="0.0" izz="0.001"/>
    </inertial>
  </link>

  <!-- Joint łączący przedni lewy punkt skrętu z kołem -->
  <joint name="front_left_joint" type="continuous">
    <parent link="steering_left"/>
    <child link="wheel_front_left"/>
    <origin xyz="0 0 0" rpy="1.57 0 0"/>
    <axis xyz="0 0 -1"/>
  </joint>

  <!-- Przednie prawe koło -->
  <link name="wheel_front_right">
    <visual>
      <geometry>
        <cylinder length="0.02" radius="0.08"/>
      </geometry>
      <material name="black">
        <color rgba="0.0 0.0 0.0 1.0"/>
      </material>
    </visual>
    <collision>
      <geometry>
        <sphere radius="0.08"/>
      </geometry>
    </collision>
    <inertial>
      <mass value="1.0"/>
      <inertia ixx="0.05" ixy="0.0" ixz="0.0" iyy="0.05" iyz="0.0" izz="0.05"/>
    </inertial>
  </link>

  <!-- Joint łączący bazę z przednim prawym punktem skrętu -->
  <joint name="right_steering_joint" type="continuous">
    <parent link="base_link"/>
    <child link="steering_right"/>
    <origin xyz="0.1 -0.06 -0.03" rpy="0 0 0"/>
    <axis xyz="0 0 1"/>
  </joint>

  <!-- Przedni prawy punkt skrętu -->
  <link name="steering_right">
    <inertial>
      <mass value="0.1"/>
      <inertia ixx="0.001" ixy="0.0" ixz="0.0" iyy="0.001" iyz="0.0" izz="0.001"/>
    </inertial>
  </link>

  <!-- Joint łączący przedni prawy punkt skrętu z kołem -->
  <joint name="front_right_joint" type="continuous">
    <parent link="steering_right"/>
    <child link="wheel_front_right"/>
    <origin xyz="0 0 0" rpy="1.57 0 0"/>
    <axis xyz="0 0 -1"/>
  </joint>

  <!-- Tylne lewe koło -->
  <link name="wheel_back_left">
    <visual>
      <geometry>
        <cylinder length="0.02" radius="0.08"/>
      </geometry>
      <material name="black">
        <color rgba="0.0 0.0 0.0 1.0"/>
      </material>
    </visual>
    <collision>
      <geometry>
        <sphere radius="0.08"/>
      </geometry>
    </collision>
    <inertial>
      <mass value="1.0"/>
      <inertia ixx="0.05" ixy="0.0" ixz="0.0" iyy="0.05" iyz="0.0" izz="0.05"/>
    </inertial>
  </link>

  <!-- Joint łączący bazę z tylnym lewym kołem -->
  <joint name="rear_left_joint" type="continuous">
    <parent link="base_link"/>
    <child link="wheel_back_left"/>
    <origin xyz="-0.1 0.06 -0.03" rpy="1.57 0 0"/>
    <axis xyz="0 0 -1"/>
  </joint>

  <!-- Tylne prawe koło -->
  <link name="wheel_back_right">
    <visual>
      <geometry>
        <cylinder length="0.02" radius="0.08"/>
      </geometry>
      <material name="black">
        <color rgba="0.0 0.0 0.0 1.0"/>
      </material>
    </visual>
    <collision>
      <geometry>
        <sphere radius="0.08"/>
      </geometry>
    </collision>
    <inertial>
      <mass value="1.0"/>
      <inertia ixx="0.05" ixy="0.0" ixz="0.0" iyy="0.05" iyz="0.0" izz="0.05"/>
    </inertial>
  </link>

  <!-- Joint łączący bazę z tylnym prawym kołem -->
  <joint name="rear_right_joint" type="continuous">
    <parent link="base_link"/>
    <child link="wheel_back_right"/>
    <origin xyz="-0.1 -0.06 -0.03" rpy="1.57 0 0"/>
    <axis xyz="0 0 -1"/>
  </joint>

  <link name="lidar_link">
    <visual>
      <geometry>
        <cylinder length="0.01" radius="0.02"/>
      </geometry>
      <material name="black">
        <color rgba="0.0 0.0 0.0 1.0"/>
      </material>
    </visual>
    <collision>
      <geometry>
        <cylinder length="0.01" radius="0.02"/>
      </geometry>
    </collision>
    <inertial>
      <mass value="1.0"/>
      <inertia ixx="0.05" ixy="0.0" ixz="0.0" iyy="0.05" iyz="0.0" izz="0.05"/>
    </inertial>
  </link>

  <joint name="lidar_joint" type="fixed">
    <parent link="base_link"/>
    <child link="lidar_link"/>
    <origin xyz="0.0 0.0 0.05" rpy="0 0 0"/>
  </joint>

  <gazebo reference="lidar_link">
  <sensor name="lidar" type="ray">
        <always_on>true</always_on>
            <visualize>true</visualize>
            <update_rate>5</update_rate>
            <ray>
                <scan>
                    <horizontal>
                        <samples>360</samples>
                        <resolution>1.000000</resolution>
                        <min_angle>0.000000</min_angle>
                        <max_angle>6.280000</max_angle>
                    </horizontal>
                </scan>
                <range>
                    <min>0.15000</min>
                    <max>3.5</max>
                    <resolution>0.015000</resolution>
                </range>
            </ray>
            <plugin name="scan" filename="libgazebo_ros_ray_sensor.so">
                <ros>
                    <remapping>~/out:=scan</remapping>
                </ros>
                <output_type>sensor_msgs/LaserScan</output_type>
                <frame_name>lidar_link</frame_name>
            </plugin>
      </sensor>
    </gazebo>

  <!-- Plugin Gazebo do obsługi dynamiki Ackermanna -->
  <gazebo>
    <plugin name="ackermann_plugin" filename="libgazebo_ros_ackermann_drive.so">
      <ros>
        <namespace>/</namespace>
        <remapping>cmd_vel:=/cmd_vel</remapping>
      </ros>

      <update_rate>100.0</update_rate>
      <command_topic>cmd_vel</command_topic>

      <publish_odom>true</publish_odom>
      <publish_odom_tf>true</publish_odom_tf>
      <publish_wheel_tf>true</publish_wheel_tf>
      <odometry_frame>odom</odometry_frame>
      <robot_base_frame>base_link</robot_base_frame>

      <front_left_joint>front_left_joint</front_left_joint>
      <front_right_joint>front_right_joint</front_right_joint>
      <rear_left_joint>rear_left_joint</rear_left_joint>
      <rear_right_joint>rear_right_joint</rear_right_joint>
      <left_steering_joint>left_steering_joint</left_steering_joint>
      <right_steering_joint>right_steering_joint</right_steering_joint>
      
      <wheel_base>0.2</wheel_base>
      <front_wheel_track>0.12</front_wheel_track>
      <rear_wheel_track>0.12</rear_wheel_track>

      <max_speed>20</max_speed>
      <max_steer>1.707</max_steer>
      <max_steering_angle>50</max_steering_angle>
      
      <left_steering_pid_gain>50 1 10</left_steering_pid_gain>
      <right_steering_pid_gain>50 1 10</right_steering_pid_gain>
      <linear_velocity_pid_gain>3 1 0.1</linear_velocity_pid_gain>
    </plugin>
  </gazebo>

  <!-- Plugin Gazebo do odometrii -->
  <gazebo>
    <plugin name="odom_plugin" filename="libgazebo_ros_p3d.so">
      <ros>
        <namespace>/</namespace>
        <remapping>odom:=/odom</remapping>
      </ros>
      <update_rate>2.0</update_rate>
      <body_name>base_link</body_name>
      <odomTopic>/odom</odomTopic>
      <robotBaseFrame>base_link</robotBaseFrame>
    </plugin>
  </gazebo>

</robot>
